Workbook

Sheet Lisez-moi
A1: Base de questions/réponses de l'assistant IA de l'UEMF : périmètre EIDIA
A2: Sources officielles consultées le 17/10/2026 sur ueuromed.org. Questions issues du site officiel, du sondage étudiant et de l'équipe cyber.
A4: À quoi sert cette base
A5: Alimenter l'assistant | B5: Les lignes marquées « Base + évaluation » sont des paires question/réponse sourcées : elles peuvent être indexées dans la base vectorielle à côté des pages officielles (étape 5).
A6: Évaluer l'assistant | B6: Toutes les lignes servent de jeu de test (étape 8) : la colonne « Réponse attendue » est la référence, « Comportement attendu » dit ce que l'assistant doit faire (répondre, orienter, refuser).
A7: Tester la sécurité | B7: Les lignes « Test de sécurité » sont des attaques simples (injection, extraction du prompt, fuite de données, jeu de rôle) à rejouer après chaque changement (étapes 9 et 10).
A8: Tester le multilingue | B8: Chaque question existe en français (avec une variante), en anglais et en arabe.
A9: Comment s'en servir
A10: Relire | B10: Deux personnes relisent chaque réponse contre sa source (lien principal), puis remplissent les colonnes jaunes « Relu par » et « Date de relecture ».
A11: Corriger | B11: Modifier la réponse, mettre à jour « Statut » (liste déroulante) et vider la note de vérification une fois le point réglé.
A12: Ajouter une question | B12: Ajouter une ligne en bas avec l'identifiant suivant (Q078...). Les compteurs de l'onglet « Résumé » se mettent à jour seuls.
A13: Exporter pour le pipeline | B13: Lancer « python export_jsonl.py base_QR_EIDIA.xlsx » : le script recrée base_QR_EIDIA.jsonl à partir de ce classeur.
A14: Signification du statut
A15: Sourcé | B15: Information trouvée sur une source officielle, sans incohérence repérée.
A16: Sourcé – à confirmer | B16: Information trouvée, mais source ancienne (2024-2025), incohérente ou mal mise en page : voir la note de vérification.
A17: Non publié sur le site | B17: L'information n'existe pas sur le site : l'assistant doit le dire et orienter vers le bon service (voir l'onglet « Infos à obtenir »).
A18: Hors périmètre | B18: Question sur des données personnelles ou en temps réel : l'assistant ne répond pas et oriente.
A19: Test de sécurité / Réponse type | B19: Lignes destinées uniquement à l'évaluation, à ne pas indexer.
A20: Limites
A21: Reformulation | B21: Les réponses sont reformulées à partir des pages officielles : relire chaque chiffre sur la source avant une démonstration.
A22: Validité | B22: Les tarifs et le calendrier valent pour 2026-2027 ; plusieurs règles de paiement viennent de l'acte d'engagement 2024-2025.
A23: Site officiel | B23: Beaucoup de fiches filières ont des rubriques vides (programme, admission, débouchés) : c'est un résultat utile pour la présentation, qui confirme le problème décrit dans la fiche projet.

Sheet Résumé
A1: Résumé de la base
A2: Les comptes se mettent à jour automatiquement à partir de l'onglet « Questions-Réponses ».
A4: Nombre total de questions | B4: =COUNTA('Questions-Réponses'!$A$5:$A$500) -> 77
A5: Questions relues | B5: =COUNTA('Questions-Réponses'!$R$5:$R$500) -> 0
A6: Avancement de la relecture | B6: =IF(B4=0,0,B5/B4) -> 0
A9: Répartition par catégorie
A10: Catégorie | B10: Nombre de Q/R
A11: Présentation de l'EIDIA | B11: =COUNTIF('Questions-Réponses'!$B$5:$B$500,A11) -> 8
A12: Formations | B12: =COUNTIF('Questions-Réponses'!$B$5:$B$500,A12) -> 13
A13: Admission | B13: =COUNTIF('Questions-Réponses'!$B$5:$B$500,A13) -> 10
A14: Frais et paiement | B14: =COUNTIF('Questions-Réponses'!$B$5:$B$500,A14) -> 11
A15: Bourses et aides | B15: =COUNTIF('Questions-Réponses'!$B$5:$B$500,A15) -> 3
A16: Calendrier et emploi du temps | B16: =COUNTIF('Questions-Réponses'!$B$5:$B$500,A16) -> 4
A17: Mobilité internationale | B17: =COUNTIF('Questions-Réponses'!$B$5:$B$500,A17) -> 3
A18: Vie étudiante | B18: =COUNTIF('Questions-Réponses'!$B$5:$B$500,A18) -> 5
A19: Logement, transport, restauration | B19: =COUNTIF('Questions-Réponses'!$B$5:$B$500,A19) -> 3
A20: Santé | B20: =COUNTIF('Questions-Réponses'!$B$5:$B$500,A20) -> 2
A21: Stages et carrière | B21: =COUNTIF('Questions-Réponses'!$B$5:$B$500,A21) -> 1
A22: Contacts | B22: =COUNTIF('Questions-Réponses'!$B$5:$B$500,A22) -> 5
... A24: Tests de sécurité | B24: =COUNTIF('Questions-Réponses'!$B$5:$B$500,A24) -> 4
A25: Total | B25: =SUM(B11:B24) -> 77
A27: Répartition par statut
A28: Statut | B28: Nombre de Q/R
A29: Sourcé | B29: =COUNTIF('Questions-Réponses'!$O$5:$O$500,A29) -> 42
A30: Sourcé – à confirmer | B30: =COUNTIF('Questions-Réponses'!$O$5:$O$500,A30) -> 20
A31: Non publié sur le site | B31: =COUNTIF('Questions-Réponses'!$O$5:$O$500,A31) -> 7
A32: Hors périmètre | B32: =COUNTIF('Questions-Réponses'!$O$5:$O$500,A32) -> 3
A33: Test de sécurité | B33: =COUNTIF('Questions-Réponses'!$O$5:$O$500,A33) -> 4
A34: Réponse type | B34: =COUNTIF('Questions-Réponses'!$O$5:$O$500,A34) -> 1
A35: Total | B35: =SUM(B29:B34) -> 77
A37: Répartition par type de question
A38: Type | B38: Nombre de Q/R
A39: Factuelle | B39: =COUNTIF('Questions-Réponses'!$N$5:$N$500,A39) -> 60
A40: Réponse partielle | B40: =COUNTIF('Questions-Réponses'!$N$5:$N$500,A40) -> 6
A41: Info non publiée | B41: =COUNTIF('Questions-Réponses'!$N$5:$N$500,A41) -> 3
A42: Hors périmètre | B42: =COUNTIF('Questions-Réponses'!$N$5:$N$500,A42) -> 3
A43: Piège de sécurité | B43: =COUNTIF('Questions-Réponses'!$N$5:$N$500,A43) -> 4
A44: Méta (assistant) | B44: =COUNTIF('Questions-Réponses'!$N$5:$N$500,A44) -> 1
A45: Total | B45: =SUM(B39:B44) -> 77
A47: Répartition par usage
...

Sheet Questions-Réponses
A1: Questions-Réponses EIDIA
A2: Remplissez uniquement les cellules jaunes (Relu par, Date de relecture) et mettez à jour le Statut avec la liste déroulante. Une ligne = une question.
A4: ID | B4: Catégorie | C4: Question (FR) | D4: Variante (FR) | E4: Question (EN) | F4: Question (AR) | G4: Réponse attendue | H4: Comportement attendu | I4: Orienter vers | J4: Sources | K4: Lien principal | L4: Validité | M4: Origine | N4: Type de question | O4: Statut | P4: Usage | Q4: Note de vérification | R4: Relu par | S4: Date de relecture
A5: Q001 | B5: Présentation de l'EIDIA | C5: Qu'est-ce que l'EIDIA ? | D5: C'est quoi l'École d'Ingénierie Digitale et d'IA de l'UEMF ? | E5: What is EIDIA? | F5: ما هي مدرسة EIDIA؟ | G5: L'EIDIA (École d'Ingénierie Digitale et d'Intelligence Artificielle) est un établissement de l'Université Euromed de Fès (UEMF), rattaché au pôle Ingénierie et Architecture. Elle forme des ingénieurs et des diplômés de master dans le numérique et l'IA : informatique, mathématiques appliquées, science des données, systèmes embarqués intelligents et technologies émergentes (blockchain, IoT, XR). Sa pédagogie repose sur les projets et l'apprentissage par l'action. | H5: Répondre et citer la source | J5: S01, S11 | K5: https://ueuromed.org/fr/etablissements/ecole-d-ingenierie-digitale-et-d-intelligence-artificielle | L5: 2026-2027 | M5: Site officiel | N5: Factuelle | O5: Sourcé | P5: Base + évaluation
A6: Q002 | B6: Présentation de l'EIDIA | C6: Depuis quand l'EIDIA existe-t-elle ? | D6: En quelle année l'EIDIA a-t-elle été créée ? | E6: When was EIDIA founded? | F6: متى تأسست مدرسة EIDIA؟ | G6: L'UEMF a lancé l'EIDIA à la rentrée 2019-2020, en partenariat avec l'École Polytechnique (France). L'école a démarré avec une centaine d'étudiants, en majorité titulaires d'un baccalauréat scientifique ou technique. | H6: Répondre et citer la source | J6: S10 | K6: https://ueuromed.org/en/etablissement/ecole-dingenierie-digitale-et-dintelligence-artificielle-eidia/mobilite-echange | L6: 2026-2027 | M6: Site officiel | N6: Factuelle | O6: Sourcé – à confirmer | P6: Base + évaluation | Q6: Information tirée de la page anglaise « Mobility and exchanges », rédigée à l'ouverture de l'école.
A7: Q003 | B7: Présentation de l'EIDIA | C7: Qui dirige l'EIDIA ? | D7: Qui est le directeur de l'EIDIA ? | E7: Who is the director of EIDIA? | F7: من هو مدير مدرسة EIDIA؟ | G7: Le directeur pédagogique de l'EIDIA est le Pr. Ahmed EL HILALI ALAOUI. L'équipe de direction comprend aussi Khaoula ALAMI CHENTOUFI (coordinatrice de direction) et Oumayma DIOURI (assistante de direction). | H7: Répondre et citer la source | J7: S01 | K7: https://ueuromed.org/fr/etablissements/ecole-d-ingenierie-digitale-et-d-intelligence-artificielle | L7: 2026-2027 | M7: Site officiel | N7: Factuelle | O7: Sourcé | P7: Base + évaluation
A8: Q004 | B8: Présentation de l'EIDIA | C8: Quels diplômes peut-on obtenir à l'EIDIA ? | D8: L'EIDIA délivre quel type de diplôme ? | E8: What degrees does EIDIA award? | F8: ما هي الشهادات التي تمنحها مدرسة EIDIA؟ | G8: L'EIDIA propose trois niveaux : le cycle préparatoire intégré (2 ans, diplôme des classes préparatoires), le cycle ingénieur (3 ans, diplôme d'Ingénieur d'État) et le master (2 ans, diplôme de Master). | H8: Répondre et citer la source | J8: S01, S03, S04, S09 | K8: https://ueuromed.org/fr/etablissements/ecole-d-ingenierie-digitale-et-d-intelligence-artificielle | L8: 2026-2027 | M8: Site officiel | N8: Factuelle | O8: Sourcé | P8: Base + évaluation
A9: Q005 | B9: Présentation de l'EIDIA | C9: Combien d'années faut-il pour devenir ingénieur à l'EIDIA ? | D9: Le cursus ingénieur dure combien de temps après le bac ? | E9: How many years does it take to become an engineer at EIDIA? | F9: كم سنة يستغرق التكوين لنيل دبلوم مهندس في EIDIA؟ | G9: Cinq ans après le baccalauréat : 2 années de cycle préparatoire intégré, puis 3 années de cycle ingénieur dans l'une des filières. | H9: Répondre et citer la source | J9: S03, S04, S10 | K9: https://ueuromed.org/fr/formations/cycle-preparatoire-integre | L9: 2026-2027 | M9: Site officiel | N9: Factuelle | O9: Sourcé | P9: Base + évaluation | Q9: La page « Mobility and exchanges » (2019) découpe ces 5 ans en 2 ans de prépa, une 3e année de tronc commun et 2 ans de spécialisation ; les fiches filières actuelles indiquent 3 ans de cycle ingénieur.
A10: Q006 | B10: Présentation de l'EIDIA | C10: Comment se passent les cours à l'EIDIA ? Quelle est la pédagogie ? | D10: C'est quoi l'APP à l'EIDIA ? | E10: What teaching approach does EIDIA use? | F10: ما هي المقاربة البيداغوجية المعتمدة في EIDIA؟ | G10: L'EIDIA privilégie la pédagogie par projets, l'apprentissage par l'action et le développement agile. Elle applique l'Approche Par Projet (APP) : les étudiants mènent des projets de l'idée jusqu'au prototype, avec les technologies digitales, la data science et l'IA. Une journée de présentation de ces projets a eu lieu en mars 2026. | H10: Répondre et citer la source | J10: S01, S22 | K10: https://ueuromed.org/fr/etablissements/ecole-d-ingenierie-digitale-et-d-intelligence-artificielle | L10: 2026-2027 | M10: Site officiel | N10: Factuelle | O10: Sourcé | P10: Base + évaluation
A11: Q007 | B11: Présentation de l'EIDIA | C11: Quel est le statut de l'Université Euromed de Fès ? | D11: L'UEMF est-elle une université publique ou privée ? | E11: What kind of institution is the Euromed University of Fes? | F11: ما هو الوضع القانوني للجامعة الأورومتوسطية بفاس؟ | G11: L'UEMF se présente comme une institution d'utilité publique à but non lucratif, labellisée par l'Union pour la Méditerranée (UpM) avec l'appui de ses 43 pays membres. Elle compte 11 établissements regroupés en 3 pôles et accueille des étudiants de plus de 50 nationalités. | H11: Répondre et citer la source | J11: S33 | K11: https://www.ueuromed.org/fr/explorer-euromed/notre-universite/uemf-en-bref | L11: 2026-2027 | M11: Site officiel | N11: Factuelle | O11: Sourcé | P11: Base + évaluation | Q11: La page ne dit pas « publique » ou « privée » : l'assistant doit reprendre la formulation officielle.
A12: Q008 | B12: Présentation de l'EIDIA | C12: Avec quelles entreprises l'EIDIA est-elle partenaire ? | D12: Quels sont les partenaires industriels de l'EIDIA ? | E12: Which companies does EIDIA partner with? | F12: ما هي الشركات الشريكة لمدرسة EIDIA؟ | G12: La page de l'EIDIA cite comme partenaires socio-économiques : Maroc Numeric Cluster, SAS Morocco, IBM Morocco, iDATE, ALTEN, AVENIS, BMCE Bank, CGEM, EMSIAD, GIMAS, HPS, Microsoft Morocco et Siemens. | H12: Répondre et citer la source | J12: S10 | K12: https://ueuromed.org/en/etablissement/ecole-dingenierie-digitale-et-dintelligence-artificielle-eidia/mobilite-echange | L12: 2026-2027 | M12: Site officiel | N12: Factuelle | O12: Sourcé – à confirmer | P12: Base + évaluation | Q12: Liste publiée à l'ouverture de l'école (2019) ; à faire confirmer par la direction.
A13: Q009 | B13: Formations | C13: Quelles sont les filières du cycle ingénieur à l'EIDIA ? | D13: Quelles spécialités peut-on choisir à l'EIDIA ? | E13: What engineering majors does EIDIA offer? | F13: ما هي التخصصات المتوفرة في سلك المهندسين بـ EIDIA؟ | G13: Cinq filières mènent au diplôme d'Ingénieur d'État (3 ans) : Computer Science and Cyber Security ; Intelligence Artificielle ; Analyse des Méga Données (Big Data Analytics) ; Robotics and Cobotics ; Full Stack Engineering and Multimedia. | H13: Répondre et citer la source | J13: S01 | K13: https://ueuromed.org/fr/etablissements/ecole-d-ingenierie-digitale-et-d-intelligence-artificielle | L13: 2026-2027 | M13: Site officiel + Sondage | N13: Factuelle | O13: Sourcé | P13: Base + évaluation
A14: Q010 | B14: Formations | C14: Qu'est-ce que le cycle préparatoire intégré de l'EIDIA ? | D14: Que fait-on pendant les deux années de prépa à l'EIDIA ? | E14: What is the integrated preparatory cycle at EIDIA? | F14: ما هو السلك التحضيري المندمج في EIDIA؟ | G14: Le cycle préparatoire intégré dure 2 ans et délivre le diplôme des classes préparatoires. Il vise à « acquérir les bases scientifiques et technologiques pour réussir en école d'ingénierie » et combine informatique, électronique, mathématiques appliquées et sciences humaines et sociales. Il donne accès aux filières du cycle ingénieur. Coordonnatrice : Pr. Sara BAKKALI (s.bakkali@insa.ueuromed.org). | H14: Répondre et citer la source | J14: S03, S02 | K14: https://ueuromed.org/fr/formations/cycle-preparatoire-integre | L14: 2026-2027 | M14: Site officiel | N14: Factuelle | O14: Sourcé | P14: Base + évaluation | Q14: E-mail recopié tel qu'affiché sur le site (domaine insa.ueuromed.org).
A15: Q011 | B15: Formations | C15: Que contient la filière Computer Science and Cyber Security ? | D15: Qu'est-ce qu'on apprend en cybersécurité à l'EIDIA ? | E15: What does the Cyber Security major at EIDIA cover? | F15: ماذا يدرس الطالب في تخصص الأمن السيبراني بـ EIDIA؟ | G15: Objectif : « maîtriser la cybersécurité et les systèmes informatiques avancés ». Durée : 3 ans, diplôme d'Ingénieur d'État. Contenus cités : cryptographie, blockchain, sécurité des réseaux, audit, architectures sécurisées, stages en entreprise. Débouchés cités : développeur en sécurité, cryptographe ou cryptanalyste. Coordonnateur : Pr. Taha AIT TCHAKOUCHT (t.ait-tchakoucht@ueuromed.org). | H15: Répondre et citer la source | J15: S04, S02 | K15: https://ueuromed.org/fr/formations/computer-science-and-cyber-security | L15: 2026-2027 | M15: Site officiel | N15: Factuelle | O15: Sourcé | P15: Base + évaluation | Q15: Le nom est écrit « AITT CHAKOUCHT » sur la fiche filière et « AIT TCHAKOUCHT » sur la page de l'école.
A16: Q012 | B16: Formations | C16: Que contient la filière Intelligence Artificielle ? | D16: Quels métiers après la filière IA de l'EIDIA ? | E16: What does the AI major at EIDIA cover? | F16: ماذا يتضمن تخصص الذكاء الاصطناعي في EIDIA؟ | G16: Objectif : « développer des solutions basées sur l'IA pour optimiser les processus et transformer les usages ». Durée : 3 ans, diplôme d'Ingénieur d'État. Contenus cités : apprentissage automatique, réseaux de neurones, traitement du langage naturel, vision par ordinateur, reconnaissance vocale, optimisation de systèmes intelligents. Débouchés cités : data engineer, développeur de chatbots. Coordonnatrice : Pr. Asmae ABADI (as.abadi@insa.ueuromed.org). | H16: Répondre et citer la source | J16: S06, S02 | K16: https://ueuromed.org/fr/formations/intelligence-artificielle | L16: 2026-2027 | M16: Site officiel | N16: Factuelle | O16: Sourcé | P16: Base + évaluation
A17: Q013 | B17: Formations | C17: Que contient la filière Analyse des Méga Données (Big Data Analytics) ? | D17: Qu'est-ce qu'on fait en Big Data à l'EIDIA ? | E17: What does the Big Data Analytics major cover? | F17: ماذا يتضمن تخصص تحليل البيانات الضخمة في EIDIA؟ | G17: Objectif : « exploiter le potentiel des données massives pour une prise de décision intelligente et stratégique ». Durée : 3 ans, diplôme d'Ingénieur d'État. Contenus cités : Java, Python, R, Hadoop, Spark, gestion de bases de données, tableaux de bord. Débouchés cités : consultant BI, développeur Big Data. Coordonnatrice : Pr. Loubna OURABAH (l.ourabah@ueuromed.org). | H17: Répondre et citer la source | J17: S05, S02 | K17: https://ueuromed.org/fr/formations/analyse-des-mega-donnees-big-data-analytics | L17: 2026-2027 | M17: Site officiel | N17: Factuelle | O17: Sourcé | P17: Base + évaluation
A18: Q014 | B18: Formations | C18: Que contient la filière Robotics and Cobotics ? | D18: La robotique à l'EIDIA, ça mène à quoi ? | E18: What does the Robotics and Cobotics major cover? | F18: ماذا يتضمن تخصص الروبوتيك والكوبوتيك في EIDIA؟ | G18: Objectif : « concevoir et piloter des systèmes robotiques intelligents pour les industries du futur ». Durée : 3 ans, diplôme d'Ingénieur d'État. Contenus cités : robots autonomes, capteurs, commande numérique, modélisation, robotique d'assistance, traitement vidéo, réalité virtuelle. Débouchés cités : ingénieur robotique en industrie, ingénieur en automatisme et robotique. Coordonnateur : Pr. Badr EL KARI (b.elkari@ueuromed.org). | H18: Répondre et citer la source | J18: S07, S02 | K18: https://ueuromed.org/fr/formations/robotics-and-cobotics | L18: 2026-2027 | M18: Site officiel | N18: Factuelle | O18: Sourcé | P18: Base + évaluation
A19: Q015 | B19: Formations | C19: Que contient la filière Full Stack Engineering and Multimedia ? | D19: Qu'apprend-on en Full Stack à l'EIDIA ? | E19: What does the Full Stack Engineering and Multimedia major cover? | F19: ماذا يتضمن تخصص هندسة Full Stack والوسائط المتعددة؟ | G19: Objectif : « créer des applications innovantes en maîtrisant les technologies web, mobile et multimédia ». Durée : 3 ans, diplôme d'Ingénieur d'État. Contenus cités : React.js, Node.js, bases SQL et NoSQL, cloud (AWS, Azure, Google Cloud), cybersécurité, compétences transversales. Débouchés cités : product manager tech, développeur full stack. Coordonnatrice : Pr. Meryem EL MOUHTADI (m.el-mouhtadi@emida.ueuromed.org). | H19: Répondre et citer la source | J19: S08, S02 | K19: https://ueuromed.org/fr/formations/full-stack-engineering-and-multimedia | L19: 2026-2027 | M19: Site officiel | N19: Factuelle | O19: Sourcé – à confirmer | P19: Base + évaluation | Q19: Domaine e-mail inhabituel (emida.ueuromed.org) : à vérifier avant diffusion.
A20: Q016 | B20: Formations | C20: Quels masters propose l'EIDIA ? | D20: Y a-t-il des masters à l'EIDIA ? | E20: Which master's programmes does EIDIA offer? | F20: ما هي برامج الماستر التي تقدمها EIDIA؟ | G20: La page de l'école présente le Master Intelligence Artificielle Générative (2 ans). La plaquette EIDIA 2026 présente aussi le Master ICT Security and Artificial Intelligence (double diplôme avec la George Washington University, enseigné entièrement en anglais) et un Master Ingénierie Full Stack et Multimédia. | H20: Répondre, signaler la limite et orienter | I20: EIDIA (+212 5 38 90-3237) | J20: S01, S09, S02 | K20: https://ueuromed.org/fr/etablissements/ecole-d-ingenierie-digitale-et-d-intelligence-artificielle | L20: 2026-2027 | M20: Site officiel | N20: Factuelle | O20: Sourcé – à confirmer | P20: Base + évaluation | Q20: La page de l'école et la plaquette 2026 ne listent pas les mêmes masters : demander à l'EIDIA lesquels ouvrent en 2026-2027.
A21: Q017 | B21: Formations | C21: Quels sont les différents masters proposés par la filière cybersécurité à l'EIDIA ? | D21: Y a-t-il un master en cybersécurité à l'EIDIA ? | E21: Is there a cybersecurity master's degree at EIDIA? | F21: هل يوجد ماستر في الأمن السيبراني في EIDIA؟ | G21: Le master lié à la cybersécurité est le Master ICT Security and Artificial Intelligence, en double diplôme avec la George Washington University. Il est enseigné entièrement en anglais et couvre la cybersécurité, l'IA et l'informatique quantique (préparation aux menaces quantiques). Débouchés cités : ingénieur systèmes de sécurité, data scientist ou analyste IA. | H21: Répondre et citer la source | J21: S02, S23, S24 | K21: https://backend.ueuromed.org/uploads/Plaquettes_EIDIA_2026.pdf | L21: 2026-2027 | M21: Sondage | N21: Factuelle | O21: Sourcé | P21: Base + évaluation
A22: Q018 | B22: Formations | C22: Quelles sont les conditions d'admission au Master ICT Security and AI ? | D22: Comment intégrer le master double diplôme avec la George Washington University ? | E22: What are the admission requirements for the ICT Security and AI master's? | F22: ما هي شروط القبول في ماستر أمن تكنولوجيا المعلومات والذكاء الاصطناعي؟ | G22: Il faut une licence (ou un bachelor) en sciences ou en ingénierie : mathématiques, informatique, physique, ou un domaine lié à l'IA, à la cybersécurité ou aux technologies, ainsi qu'un niveau d'anglais suffisant. La sélection se fait sur étude du dossier, concours écrit et entretien oral. | H22: Répondre et citer la source | J22: S02, S24 | K22: https://backend.ueuromed.org/uploads/Plaquettes_EIDIA_2026.pdf | L22: 2026-2027 | M22: Site officiel | N22: Factuelle | O22: Sourcé | P22: Base + évaluation
A23: Q019 | B23: Formations | C23: Qu'est-ce que le Master Intelligence Artificielle Générative ? | D23: Le master IA générative dure combien de temps ? | E23: What is the Generative AI master's at EIDIA? | F23: ما هو ماستر الذكاء الاصطناعي التوليدي؟ | G23: C'est un master de 2 ans de l'EIDIA, présenté comme « une formation spécialisée dans les technologies avancées de l'intelligence artificielle », centré sur les modèles génératifs et leurs applications. Coordonnatrice : Pr. Oumaima MOUTIK (o.moutik@ueuromed.org). Le programme et les conditions d'admission propres à ce master ne sont pas détaillés sur la page. | H23: Répondre, signaler la limite et orienter | I23: Pr. Oumaima MOUTIK | J23: S09 | K23: https://ueuromed.org/fr/formations/master-intelligence-artificielle-generative | L23: 2026-2027 | M23: Site officiel | N23: Factuelle | O23: Sourcé | P23: Base + évaluation
A24: Q020 | B24: Formations | C24: En quelle langue sont donnés les cours à l'EIDIA ? | D24: Les cours sont-ils en français ou en anglais ? | E24: What language are classes taught in at EIDIA? | F24: ما هي لغة التدريس في EIDIA؟ | G24: Les fiches des filières ne précisent pas la langue d'enseignement. Seul le Master ICT Security and Artificial Intelligence est indiqué comme enseigné entièrement en anglais. Pour une filière précise, contactez son coordonnateur ou l'EIDIA (+212 5 38 90-3237). | H24: Répondre, signaler la limite et orienter | I24: Coordonnateur de filière / EIDIA | J24: S02, S04 | K24: https://backend.ueuromed.org/uploads/Plaquettes_EIDIA_2026.pdf | L24: 2026-2027 | M24: Site officiel | N24: Réponse partielle | O24: Non publié sur le site | P24: Base + évaluation
A25: Q021 | B25: Formations | C25: Où trouver le programme détaillé (modules par semestre) d'une filière ? | D25: Quels sont les modules de 4e année en Big Data ? | E25: Where can I find the detailed course list for a major? | F25: أين أجد البرنامج المفصل لتخصص معين؟ | G25: Le programme détaillé par semestre n'est pas publié : sur les fiches filières du site, la rubrique « Programme de formation » est vide. La plaquette EIDIA 2026 donne seulement les grands contenus de chaque filière. Pour la liste des modules, contactez le coordonnateur de la filière. | H25: Dire que l'info n'est pas publiée et orienter | I25: Coordonnateur de filière | J25: S02, S05 | K25: https://backend.ueuromed.org/uploads/Plaquettes_EIDIA_2026.pdf | L25: 2026-2027 | M25: Site officiel | N25: Info non publiée | O25: Non publié sur le site | P25: Base + évaluation
A26: Q022 | B26: Admission | C26: Comment intégrer l'EIDIA après le bac ? | D26: Quelles sont les conditions d'accès en 1re année ? | E26: How can I join EIDIA after high school? | F26: كيف يمكنني الالتحاق بـ EIDIA بعد البكالوريا؟ | G26: L'entrée en 1re année se fait en cycle préparatoire intégré, avec un baccalauréat scientifique. La plaquette EIDIA 2026 mentionne une sélection par concours, en présentiel ou à distance selon les circonstances. La candidature se dépose en ligne sur candidature.ueuromed.org. | H26: Répondre et citer la source | J26: S02, S15 | K26: https://backend.ueuromed.org/uploads/Plaquettes_EIDIA_2026.pdf | L26: 2026-2027 | M26: Site officiel | N26: Factuelle | O26: Sourcé – à confirmer | P26: Base + évaluation | Q26: La mise en page de la plaquette 2026 est décalée (titres et textes mal alignés) : relire les conditions d'admission directement sur le PDF.
A27: Q023 | B27: Admission | C27: Peut-on intégrer directement le cycle ingénieur avec un bac+2 ? | D27: J'ai un DUT ou un DEUG, puis-je entrer à l'EIDIA ? | E27: Can I enter the engineering cycle directly after two years of higher education? | F27: هل يمكن الالتحاق مباشرة بسلك المهندسين بعد سنتين من الدراسة الجامعية؟ | G27: La plaquette EIDIA 2026 cite comme profils admissibles les candidats ayant réussi le concours national d'admission aux écoles d'ingénieurs, ou titulaires d'un DEUG, DUT, DEUST, DEUP, MIP, MPC, génie informatique, ou d'une spécialité jugée équivalente par la commission. La sélection se fait sur étude du dossier et entretien oral. | H27: Répondre, signaler la limite et orienter | I27: Service des admissions (+212 5 38 90-3230) | J27: S02 | K27: https://backend.ueuromed.org/uploads/Plaquettes_EIDIA_2026.pdf | L27: 2026-2027 | M27: Site officiel | N27: Factuelle | O27: Sourcé – à confirmer | P27: Base + évaluation | Q27: Dans le PDF, cette liste apparaît sous le titre « Accès à la première année du cycle préparatoire », probablement à cause du décalage de mise en page : elle correspond logiquement à l'entrée en cycle ingénieur. À confirmer avec le service des admissions.
A28: Q024 | B28: Admission | C28: Peut-on intégrer l'EIDIA avec une licence ? | D28: Admission parallèle en 2e année du cycle ingénieur : quelles conditions ? | E28: Can I join EIDIA with a bachelor's degree? | F28: هل يمكن الالتحاق بـ EIDIA بشهادة الإجازة؟ | G28: Oui. D'après la plaquette EIDIA 2026, les titulaires d'une licence ou d'un diplôme équivalent dans une spécialité scientifique, avec les prérequis nécessaires, peuvent être admis en 2e année du cycle ingénieur après étude du dossier et entretien oral. Une licence en sciences ou en ingénierie permet aussi de candidater en master (dossier, concours écrit et entretien oral). | H28: Répondre et citer la source | J28: S02 | K28: https://backend.ueuromed.org/uploads/Plaquettes_EIDIA_2026.pdf | L28: 2026-2027 | M28: Site officiel | N28: Factuelle | O28: Sourcé – à confirmer | P28: Base + évaluation | Q28: Même réserve de mise en page que Q022 et Q023.
A29: Q025 | B29: Admission | C29: Comment déposer ma candidature à l'UEMF ? | D29: Quelles sont les modalités d'inscription au sein de l'établissement ? | E29: How do I apply to UEMF? | F29: كيف أقدم ترشيحي للجامعة الأورومتوسطية بفاس؟ | G29: La candidature se fait en ligne, en trois étapes : découvrir les formations, préparer son dossier, puis candidater sur la plateforme candidature.ueuromed.org. Le suivi de la candidature se fait sur la même plateforme (candidature.ueuromed.org/Login). | H29: Répondre et citer la source | J29: S35, S15, S14 | K29: https://www.ueuromed.org/fr | L29: 2026-2027 | M29: Site officiel + Sondage | N29: Factuelle | O29: Sourcé | P29: Base + évaluation
A30: Q026 | B30: Admission | C30: Quelles pièces faut-il pour candidater en 1re année ? | D30: Quels documents mettre dans le dossier de candidature après le bac ? | E30: What documents are required to apply for first year? | F30: ما هي الوثائق المطلوبة للترشح للسنة الأولى؟ | G30: Pour une admission en 1re année : une photo d'identité récente (JPG ou PDF) ; une copie de la CIN (Marocains) ou du passeport (étudiants internationaux) ; le relevé de notes du baccalauréat (si disponible) ; le relevé de notes détaillé du baccalauréat régional ; les relevés de notes de la 1re année du baccalauréat (1er et 2e semestres) ; le relevé de notes du 1er semestre de la 2e année du baccalauréat. Il faut aussi joindre l'acte d'engagement signé. | H30: Répondre et citer la source | J30: S14 | K30: https://www.ueuromed.org/fr/dossier-de-candidature | L30: 2026-2027 | M30: Site officiel | N30: Factuelle | O30: Sourcé | P30: Base + évaluation
A31: Q027 | B31: Admission | C31: Quelles pièces faut-il pour une admission parallèle ou un master ? | D31: Dossier de candidature pour le master : quels documents ? | E31: What documents are required for advanced-standing or master's applications? | F31: ما هي الوثائق المطلوبة للقبول الموازي أو للماستر؟ | G31: En plus des pièces de 1re année : les relevés de notes des années après le bac (licence, master, etc.), tout diplôme ou attestation de réussite post-bac, et l'attestation d'équivalence pour un diplôme étranger. Sont aussi recommandés : une lettre de motivation (fortement conseillée pour les masters), un CV à jour et des lettres de recommandation. | H31: Répondre et citer la source | J31: S14 | K31: https://www.ueuromed.org/fr/dossier-de-candidature | L31: 2026-2027 | M31: Site officiel | N31: Factuelle | O31: Sourcé | P31: Base + évaluation
A32: Q028 | B32: Admission | C32: Qu'est-ce que l'acte d'engagement du dossier de candidature ? | D32: Comment remplir l'acte d'engagement ? | E32: What is the commitment form (acte d'engagement)? | F32: ما هو عقد الالتزام في ملف الترشح؟ | G32: C'est un document à télécharger selon votre pôle (l'EIDIA relève du pôle Ingénierie et Architecture), à imprimer sur une seule feuille recto-verso, à signer et à joindre au dossier. Il fixe notamment les frais, l'échéancier de paiement, les réductions et les règles en cas de retard ou de désistement. | H32: Répondre et citer la source | J32: S14, S34 | K32: https://www.ueuromed.org/fr/dossier-de-candidature | L32: 2026-2027 | M32: Site officiel | N32: Factuelle | O32: Sourcé | P32: Base + évaluation | Q32: Le contenu décrit s'appuie sur l'acte 2024-2025 ; le lien vers l'acte 2026-2027 n'apparaît pas sur la page.
A33: Q029 | B33: Admission | C33: Je suis étudiant étranger : comment candidater ? | D33: Les étudiants internationaux peuvent-ils s'inscrire à l'EIDIA ? | E33: I'm an international student. How do I apply? | F33: أنا طالب أجنبي، كيف أترشح؟ | G33: La procédure en ligne est la même, avec deux différences dans le dossier : une copie du passeport (au lieu de la CIN) et, pour un diplôme étranger, une attestation d'équivalence. L'UEMF indique accueillir chaque année des étudiants de plus de 48 nationalités et les accompagner pour l'intégration, les démarches administratives et l'installation au Maroc. | H33: Répondre et citer la source | J33: S14, S16 | K33: https://www.ueuromed.org/fr/dossier-de-candidature | L33: 2026-2027 | M33: Site officiel | N33: Factuelle | O33: Sourcé | P33: Base + évaluation
A34: Q030 | B34: Admission | C34: Quand a lieu le concours d'entrée à l'EIDIA ? | D34: Quelles sont les dates de candidature pour l'an prochain ? | E34: When is the EIDIA entrance exam? | F34: متى تجرى مباراة الولوج إلى EIDIA؟ | G34: Les dates du concours et du calendrier des admissions ne sont pas publiées sur les pages officielles consultées. Pour les connaître, contactez le service des admissions (+212 5 38 90-3230) ou consultez la plateforme candidature.ueuromed.org. | H34: Dire que l'info n'est pas publiée et orienter | I34: Service des admissions (+212 5 38 90-3230) | J34: S17, S15 | K34: https://www.ueuromed.org/fr/contact | L34: 2026-2027 | M34: Site officiel | N34: Info non publiée | O34: Non publié sur le site | P34: Base + évaluation
A35: Q031 | B35: Admission | C35: Combien coûtent les frais de concours ? | D35: Faut-il payer pour passer le concours ? | E35: Is there an entrance exam fee? | F35: كم تبلغ رسوم المباراة؟ | G35: Oui, des frais de concours sont à régler lors de l'inscription au concours d'admission, mais leur montant n'est pas publié sur le site. Renseignez-vous auprès du service des admissions (+212 5 38 90-3230). | H35: Dire que l'info n'est pas publiée et orienter | I35: Service des admissions (+212 5 38 90-3230) | J35: S12, S11 | K35: https://ueuromed.org/fr/construire-mon-parcours/bourses-aides-financieres | L35: 2026-2027 | M35: Site officiel | N35: Réponse partielle | O35: Non publié sur le site | P35: Base + évaluation
A36: Q032 | B36: Frais et paiement | C36: Combien coûte une année de cycle préparatoire à l'EIDIA ? | D36: Frais de scolarité en 1re année à l'EIDIA ? | E36: How much is tuition for the preparatory years at EIDIA? | F36: كم تبلغ رسوم الدراسة في السنوات التحضيرية بـ EIDIA؟ | G36: En 2026-2027, pour les 1re et 2e années préparatoires (EIDIA et EPS) : 65 700 DH par an au total, frais d'inscription de 5 000 DH compris. Échéancier : 5 000 DH à l'inscription, puis 20 000 DH avant le 2 septembre, 20 000 DH avant le 31 décembre et 20 000 DH avant le 31 mars. | H36: Répondre et citer la source | J36: S11 | K36: https://ueuromed.org/fr/tarification-et-reduction | L36: 2026-2027 | M36: Site officiel | N36: Factuelle | O36: Sourcé – à confirmer | P36: Base + évaluation | Q36: Inscription + 3 tranches = 65 000 DH, soit 700 DH de moins que le total affiché ; la page n'explique pas l'écart. À clarifier avec le service financier.
A37: Q033 | B37: Frais et paiement | C37: Combien coûte une année de cycle ingénieur à l'EIDIA ? | D37: Frais de scolarité en 3e, 4e ou 5e année ? | E37: How much is tuition for the engineering cycle? | F37: كم تبلغ رسوم الدراسة في سلك المهندسين؟ | G37: En 2026-2027, pour les 1re, 2e et 3e années du cycle ingénieur (EIDIA et EPS) : 75 700 DH par an au total, frais d'inscription de 5 000 DH compris. Échéancier : 5 000 DH à l'inscription, puis 20 000 DH avant le 2 septembre, 25 000 DH avant le 31 décembre et 25 000 DH avant le 31 mars. | H37: Répondre et citer la source | J37: S11 | K37: https://ueuromed.org/fr/tarification-et-reduction | L37: 2026-2027 | M37: Site officiel | N37: Factuelle | O37: Sourcé – à confirmer | P37: Base + évaluation | Q37: Inscription + 3 tranches = 75 000 DH, soit 700 DH de moins que le total affiché. À clarifier avec le service financier.
A38: Q034 | B38: Frais et paiement | C38: Combien coûte un master à l'EIDIA ? | D38: Frais de scolarité du master IA générative ? | E38: How much is tuition for a master's at EIDIA? | F38: كم تبلغ رسوم الماستر في EIDIA؟ | G38: En 2026-2027, pour le cycle master (EIDIA, EPS, EMADU) : 60 700 DH par an au total, frais d'inscription de 5 000 DH compris. Échéancier : 5 000 DH à l'inscription, puis 15 000 DH avant le 2 septembre, 20 000 DH avant le 31 décembre et 20 000 DH avant le 31 mars. | H38: Répondre et citer la source | J38: S11 | K38: https://ueuromed.org/fr/tarification-et-reduction | L38: 2026-2027 | M38: Site officiel | N38: Factuelle | O38: Sourcé – à confirmer | P38: Base + évaluation | Q38: Même écart de 700 DH. La grille ne dit pas si le Master ICT Security and AI (double diplôme GWU) suit ce tarif.
A39: Q035 | B39: Frais et paiement | C39: Quels sont les prix de la scolarité par filière ? | D39: La filière cybersécurité coûte-t-elle plus cher que la filière IA ? | E39: Does tuition differ by major? | F39: هل تختلف الرسوم حسب التخصص؟ | G39: À l'EIDIA, le tarif dépend du cycle et non de la filière. En 2026-2027 : 65 700 DH par an en cycle préparatoire, 75 700 DH par an en cycle ingénieur (quelle que soit la filière) et 60 700 DH par an en master, frais d'inscription de 5 000 DH compris. | H39: Répondre et citer la source | J39: S11 | K39: https://ueuromed.org/fr/tarification-et-reduction | L39: 2026-2027 | M39: Sondage | N39: Factuelle | O39: Sourcé | P39: Base + évaluation
A40: Q036 | B40: Frais et paiement | C40: Y a-t-il une réduction si je paie toute l'année d'un coup ? | D40: Réduction pour paiement anticipé ? | E40: Is there a discount for paying the full year upfront? | F40: هل يوجد تخفيض عند أداء رسوم السنة كاملة دفعة واحدة؟ | G40: Oui : 5 % de réduction pour les étudiants non boursiers qui règlent l'intégralité des frais de scolarité à l'inscription, avant le 2 septembre 2026. | H40: Répondre et citer la source | J40: S11 | K40: https://ueuromed.org/fr/tarification-et-reduction | L40: 2026-2027 | M40: Site officiel | N40: Factuelle | O40: Sourcé | P40: Base + évaluation
A41: Q037 | B41: Frais et paiement | C41: Existe-t-il des réductions pour les fratries ou d'autres cas ? | D41: Mon frère est aussi à l'UEMF, ai-je droit à une réduction ? | E41: Are there sibling discounts or other reductions? | F41: هل توجد تخفيضات للإخوة أو حالات أخرى؟ | G41: L'acte d'engagement 2024-2025 du pôle Ingénierie prévoyait : 20 % si un parent est affilié aux Forces Armées Royales ; 20 %, 25 % et 30 % pour le 2e, 3e et 4e enfant d'une même fratrie inscrite à l'UEMF la même année ; 10 % ou 20 % si un parent est affilié au ministère de l'Économie et des Finances (selon convention) ; 50 % pour un étudiant ajourné qui refait moins de la moitié du programme. La demande se dépose sur le portail et en version papier au service de scolarité, avant la mi-octobre. | H41: Répondre, signaler la limite et orienter | I41: Service de scolarité (+212 5 38 90-3210) | J41: S34 | K41: https://ueuromed.org/sites/default/files/2024-06/ok%20Acte%20d'engagement%2024-25%20P%C3%B4le%20Ing%20&%20SHS%20UEMF.pdf | L41: 2024-2025 | M41: Site officiel | N41: Factuelle | O41: Sourcé – à confirmer | P41: Base + évaluation | Q41: Règles 2024-2025 (date limite : 15 octobre 2024). La page des tarifs 2026-2027 ne mentionne que la réduction de 5 %. Vérifier l'acte d'engagement 2026-2027.
...

Sheet Sources
A1: Inventaire des sources
A2: Sources officielles consultées le 17/10/2026. « Utilisée par » compte les questions qui citent la source (formule).
A4: ID | B4: Titre | C4: URL | D4: Type | E4: Thème | F4: Langue | G4: Contenu exploitable | H4: Remarques | I4: Utilisée par (nb de Q/R)
A5: S00 | B5: Fiche de présentation du projet (document interne) | D5: Document interne | E5: Périmètre de l'assistant | F5: FR | G5: Référence interne | H5: Sert uniquement à définir ce que l'assistant fait et ne fait pas. | I5: =COUNTIF('Questions-Réponses'!$J$5:$J$500,"*"&A5&"*") -> 3
A6: S01 | B6: Page de l'école EIDIA | C6: https://ueuromed.org/fr/etablissements/ecole-d-ingenierie-digitale-et-d-intelligence-artificielle | D6: Page web | E6: Présentation, direction, filières, corps enseignant | F6: FR | G6: Riche | H6: Liste les filières, la direction et les enseignants. Pas de frais ni de conditions d'admission. | I6: =COUNTIF('Questions-Réponses'!$J$5:$J$500,"*"&A6&"*") -> 8
A7: S02 | B7: Plaquette EIDIA 2026 | C7: https://backend.ueuromed.org/uploads/Plaquettes_EIDIA_2026.pdf | D7: PDF | E7: Filières, débouchés, admission, masters | F7: FR | G7: Riche | H7: Mise en page décalée : certains titres ne sont pas alignés avec leur texte (conditions d'admission). Relire le PDF avant de figer les réponses. | I7: =COUNTIF('Questions-Réponses'!$J$5:$J$500,"*"&A7&"*") -> 15
A8: S03 | B8: Fiche formation : Cycle Préparatoire Intégré | C8: https://ueuromed.org/fr/formations/cycle-preparatoire-integre | D8: Page web | E8: Formation | F8: FR | G8: Partiel | H8: Durée, diplôme et coordonnatrice seulement ; les rubriques programme, admission et débouchés sont vides. | I8: =COUNTIF('Questions-Réponses'!$J$5:$J$500,"*"&A8&"*") -> 4
A9: S04 | B9: Fiche formation : Computer Science and Cyber Security | C9: https://ueuromed.org/fr/formations/computer-science-and-cyber-security | D9: Page web | E9: Formation | F9: FR | G9: Partiel | H9: Rubriques programme, admission et débouchés vides. Nom du coordonnateur orthographié « AITT CHAKOUCHT ». | I9: =COUNTIF('Questions-Réponses'!$J$5:$J$500,"*"&A9&"*") -> 5
A10: S05 | B10: Fiche formation : Analyse des Méga Données (Big Data Analytics) | C10: https://ueuromed.org/fr/formations/analyse-des-mega-donnees-big-data-analytics | D10: Page web | E10: Formation | F10: FR | G10: Partiel | H10: Rubriques programme, admission et débouchés vides. | I10: =COUNTIF('Questions-Réponses'!$J$5:$J$500,"*"&A10&"*") -> 3
A11: S06 | B11: Fiche formation : Intelligence Artificielle | C11: https://ueuromed.org/fr/formations/intelligence-artificielle | D11: Page web | E11: Formation | F11: FR | G11: Partiel | H11: Rubriques programme, admission et débouchés vides. | I11: =COUNTIF('Questions-Réponses'!$J$5:$J$500,"*"&A11&"*") -> 2
A12: S07 | B12: Fiche formation : Robotics and Cobotics | C12: https://ueuromed.org/fr/formations/robotics-and-cobotics | D12: Page web | E12: Formation | F12: FR | G12: Partiel | H12: Rubriques programme, admission et débouchés vides. | I12: =COUNTIF('Questions-Réponses'!$J$5:$J$500,"*"&A12&"*") -> 2
A13: S08 | B13: Fiche formation : Full Stack Engineering and Multimedia | C13: https://ueuromed.org/fr/formations/full-stack-engineering-and-multimedia | D13: Page web | E13: Formation | F13: FR | G13: Partiel | H13: Rubriques vides. E-mail de la coordonnatrice sur un domaine inhabituel (emida.ueuromed.org). | I13: =COUNTIF('Questions-Réponses'!$J$5:$J$500,"*"&A13&"*") -> 2
A14: S09 | B14: Fiche formation : Master Intelligence Artificielle Générative | C14: https://ueuromed.org/fr/formations/master-intelligence-artificielle-generative | D14: Page web | E14: Formation | F14: FR | G14: Partiel | H14: Durée, diplôme et coordonnatrice seulement. | I14: =COUNTIF('Questions-Réponses'!$J$5:$J$500,"*"&A14&"*") -> 4
A15: S10 | B15: EIDIA : Mobility and exchanges (page anglaise) | C15: https://ueuromed.org/en/etablissement/ecole-dingenierie-digitale-et-dintelligence-artificielle-eidia/mobilite-echange | D15: Page web | E15: Historique, partenaires, mobilité | F15: EN | G15: Partiel | H15: Contenu rédigé à l'ouverture de l'école (2019) : à confirmer pour l'année en cours. La version française de la page ne répondait pas. | I15: =COUNTIF('Questions-Réponses'!$J$5:$J$500,"*"&A15&"*") -> 4
A16: S11 | B16: Tarification et réduction 2026-2027 | C16: https://ueuromed.org/fr/tarification-et-reduction | D16: Page web | E16: Frais de scolarité | F16: FR | G16: Riche | H16: Pôle Ingénierie seulement. Écart de 700 DH entre le total affiché et la somme inscription + tranches, non expliqué. | I16: =COUNTIF('Questions-Réponses'!$J$5:$J$500,"*"&A16&"*") -> 9
A17: S12 | B17: Bourses et aides financières | C17: https://ueuromed.org/fr/construire-mon-parcours/bourses-aides-financieres | D17: Page web | E17: Bourses, prêt, types de frais | F17: FR | G17: Partiel | H17: Détaille le prêt « Enseignement Plus » ; les bourses ne sont pas détaillées ici. | I17: =COUNTIF('Questions-Réponses'!$J$5:$J$500,"*"&A17&"*") -> 3
... A32: S27 | B32: S'épanouir à l'UEMF (clubs, sport) | C32: https://www.ueuromed.org/fr/sepanouir-a-l-uemf | D32: Page web | E32: Vie étudiante | F32: FR | G32: Riche | H32: Liste des clubs ; pas de procédure d'adhésion. | I32: =COUNTIF('Questions-Réponses'!$J$5:$J$500,"*"&A32&"*") -> 2
A33: S28 | B33: Club SparkSec | C33: https://www.ueuromed.org/fr/clubs/spark-sec | D33: Page web | E33: Vie étudiante | F33: FR | G33: Riche | I33: =COUNTIF('Questions-Réponses'!$J$5:$J$500,"*"&A33&"*") -> 1
A34: S29 | B34: Club HI-TEC | C34: https://www.ueuromed.org/fr/clubs/hi-tec | D34: Page web | E34: Vie étudiante | F34: FR | G34: Riche | I34: =COUNTIF('Questions-Réponses'!$J$5:$J$500,"*"&A34&"*") -> 1
A35: S30 | B35: Préparer son avenir | C35: https://www.ueuromed.org/fr/preparer-son-avenir | D35: Page web | E35: Orientation, stages, soft skills | F35: FR | G35: Partiel | I35: =COUNTIF('Questions-Réponses'!$J$5:$J$500,"*"&A35&"*") -> 2
A36: S31 | B36: Stage, alternance, mentorat | C36: https://www.ueuromed.org/fr/stage-alternance-mentorat | D36: Page web | E36: Stages | F36: FR | G36: Partiel | H36: Le lien « Voir les offres de stage » pointe vers un domaine externe inhabituel (ueuromed.content-website.xyz) : à signaler, ne pas l'indexer. | I36: =COUNTIF('Questions-Réponses'!$J$5:$J$500,"*"&A36&"*") -> 1
A37: S32 | B37: Services santé et bien-être | C37: https://www.ueuromed.org/fr/services-sante-bien-etre | D37: Page web | E37: Santé, AMO | F37: FR | G37: Riche | I37: =COUNTIF('Questions-Réponses'!$J$5:$J$500,"*"&A37&"*") -> 2
A38: S33 | B38: UEMF en bref | C38: https://www.ueuromed.org/fr/explorer-euromed/notre-universite/uemf-en-bref | D38: Page web | E38: Présentation UEMF | F38: FR | G38: Partiel | I38: =COUNTIF('Questions-Réponses'!$J$5:$J$500,"*"&A38&"*") -> 2
A39: S34 | B39: Acte d'engagement 2024-2025, pôles Ingénierie & Architecture et SHS | C39: https://ueuromed.org/sites/default/files/2024-06/ok%20Acte%20d'engagement%2024-25%20P%C3%B4le%20Ing%20&%20SHS%20UEMF.pdf | D39: PDF | E39: Paiement, réductions, désistement | F39: FR | G39: Riche (ancien) | H39: Document 2024-2025 : à remplacer par l'acte 2026-2027 dès qu'il est obtenu. | I39: =COUNTIF('Questions-Réponses'!$J$5:$J$500,"*"&A39&"*") -> 7
A40: S35 | B40: Page d'accueil UEMF | C40: https://www.ueuromed.org/fr | D40: Page web | E40: Navigation, contacts, événements | F40: FR | G40: Partiel | H40: Liens vers candidature, espace étudiant, événements et actualités. | I40: =COUNTIF('Questions-Réponses'!$J$5:$J$500,"*"&A40&"*") -> 5
A41: S36 | B41: La vie à l'UEMF | C41: https://www.ueuromed.org/fr/la-vie-a-l-uemf | D41: Page web | E41: Vie étudiante | F41: FR | G41: Pauvre | H41: Page de rubriques ; renvoie vers S25, S27 et S30. | I41: =COUNTIF('Questions-Réponses'!$J$5:$J$500,"*"&A41&"*") -> 0
A42: S37 | B42: Le quotidien à l'UEMF | C42: https://www.ueuromed.org/fr/le-quotidien-a-luemf | D42: Page web | E42: Vie pratique | F42: FR | G42: Pauvre | H42: Page de rubriques ; renvoie vers S18, S25 et S32. | I42: =COUNTIF('Questions-Réponses'!$J$5:$J$500,"*"&A42&"*") -> 0

Sheet Couverture sondage
A1: Questions du sondage et couverture par la base
A2: Questions libres du formulaire « Quelles questions aimeriez-vous poser à ce chatbot ? » (réponses vides ou « je ne sais pas » retirées, adresses e-mail non reprises).
A4: N° | B4: Question posée dans le sondage | C4: Établissement du répondant | D4: Q/R liées | E4: Couverture | F4: Commentaire
A5: 1 | B5: Combien d'heures d'absence j'ai. | C5: EIDIA | D5: Q069 | E5: Hors périmètre | F5: Donnée personnelle : orienter vers l'espace étudiant.
A6: 2 | B6: Quels sont les différents Master proposé par la filière cybersecurité à l'EIDIA | C6: EIDIA | D6: Q016, Q017 | E6: Couverte
A7: 3 | B7: Les prix de la scolarité par filière | C7: EIDIA | D7: Q035, Q032, Q033, Q034 | E7: Couverte | F7: Le tarif dépend du cycle, pas de la filière.
A8: 4 | B8: Des questions en rapport avec la scolarité | C8: Euromed Polytechnic School | D8: Q032 à Q042 | E8: Couverte | F8: Question vague : couverte par la catégorie Frais et paiement.
A9: 5 | B9: Tout type de questions personnelles, après avoir accédé à son compte après l'inscription | C9: EIDIA | D9: Q069, Q073 | E9: Hors périmètre | F9: Nécessiterait une connexion au compte étudiant : hors du prototype.
A10: 6 | B10: Une question qui donnerait une réponse bien précise, pour ne pas avoir à se déplacer | C10: École d'Ingénieur en Biomédical et Biotechnologie | D10: Q073 | E10: Attente générale | F10: Attente de précision : à mesurer dans l'évaluation.
A11: 7 | B11: Quelles sont les modalités d'inscriptions au sein de l'établissement | C11: Faculté de Médecine Dentaire | D11: Q025 à Q029 | E11: Couverte
A12: 8 | B12: Des questions d'orientation | C12: École d'Ingénieur en Biomédical et Biotechnologie | D12: Q072, Q009 | E12: Partielle | F12: Pas de test d'orientation publié.
A13: 9 | B13: Quelle est notre activité de demain ? | C13: Institut des Sciences Juridiques et Politiques | D13: Q070 | E13: Hors périmètre | F13: Donnée personnelle en temps réel.
A14: 10 | B14: Sera-t-il facile à utiliser ? | C14: Faculté des Sciences Infirmières et Techniques de Santé | D14: Q073 | E14: Méta | F14: Question sur l'assistant lui-même.
A15: 11 | B15: Les nouveaux bâtiments de l'université | C15: EIDIA | D15: Q071 | E15: Non trouvée | F15: Aucune source officielle trouvée.
A16: 12 | B16: What is my planing for today ? | C16: EIDIA | D16: Q070 | E16: Hors périmètre | F16: Question en anglais : utile pour le test multilingue.
A17: 13 | B17: Est-ce que tous les cours de la semaine sont maintenus ? | C17: Euromed Business School | D17: Q049 | E17: Hors périmètre | F17: Information en temps réel.
A18: 14 | B18: Où je peux payer ma scolarité | C18: EIDIA | D18: Q039 | E18: Couverte | F18: Source 2024-2025 à actualiser.
A19: 15 | B19: Quels sont les différents moyens de paiement de scolarité ? Ou moyen d'admission ? | C19: EIDIA | D19: Q039, Q025 | E19: Couverte | F19: Source 2024-2025 à actualiser.
A20: 16 | B20: Quels sont les critères pour les échanges universitaires ainsi que les frais supplémentaires | C20: Euromed Business School | D20: Q051, Q050 | E20: Partielle | F20: Frais supplémentaires non publiés.
A21: 17 | B21: Méthode pour obtenir des bourses pour les anciens étudiants de l'UEMF | C21: Euromed Business School | D21: Q044, Q043 | E21: Partielle | F21: Procédure de demande non publiée.
A22: 18 | B22: Pourrais-je avoir le calendrier des examens du premier semestre ? | C22: Faculté de Médecine Dentaire | D22: Q047 | E22: Partielle | F22: Dates d'examens à saisir depuis le PDF du calendrier.
A23: 19 | B23: Qui est en charge de la gestion des programmes du cycle polytechnique ? | C23: Euromed Polytechnic School | D23: Q067 | E23: Partielle | F23: Hors EIDIA ; équivalent EIDIA : coordonnatrice du cycle préparatoire.
A24: 20 | B24: Annuaire de contacts regroupant les adresses e-mail des différents pôles (suggestion) | C24: Euromed Polytechnic School | D24: Q064, Q065, Q067 | E24: Partielle | F24: Pas d'e-mail par service sur le site, seulement des téléphones.
A25: 21 | B25: Je cherche des informations sur les événements | C25: Euromed Polytechnic School | D25: Q057 | E25: Couverte
A26: 22 | B26: Une question sur les réelles formations proposées aux nouveaux étudiants | C26: Euromed Polytechnic School | D26: Q004, Q009, Q010 | E26: Couverte
A27: 23 | B27: Les conditions d'amélioration et un test d'orientation | C27: EIDIA | D27: Q072 | E27: Partielle

Sheet Infos à obtenir
A1: Informations absentes ou à confirmer
A2: À demander aux professeurs et à l'administration (voir « Ce que nous demandons » dans la fiche projet). Remplissez les colonnes jaunes au fil des réponses.
A4: N° | B4: Information à obtenir | C4: Pourquoi | D4: Service à contacter | E4: Q/R concernées | F4: Priorité | G4: Responsable | H4: Obtenu le
A5: 1 | B5: Dates du concours et calendrier des admissions | C5: Absentes du site ; demande fréquente des futurs étudiants. | D5: Service des admissions | E5: Q030 | F5: Haute
A6: 2 | B6: Montant des frais de concours | C6: Mentionnés sans montant. | D6: Service des admissions | E6: Q031 | F6: Haute
A7: 3 | B7: Explication de l'écart de 700 DH entre le total et inscription + tranches | C7: Le total affiché ne correspond pas à la somme des paiements. | D7: Service financier | E7: Q032, Q033, Q034 | F7: Haute
A8: 4 | B8: Acte d'engagement 2026-2027 (réductions, frais divers, moyens de paiement, désistement) | C8: Les réponses actuelles reposent sur l'acte 2024-2025. | D8: Service de scolarité | E8: Q028, Q037, Q039 à Q042, Q068 | F8: Haute
A9: 5 | B9: Dates d'examens S1 et S2 2026-2027 | C9: Le PDF du calendrier n'est pas lisible automatiquement : saisie manuelle nécessaire. | D9: Équipe projet (saisie depuis le PDF) | E9: Q047 | F9: Haute
A10: 6 | B10: Programme détaillé (modules par semestre) de chaque filière et master | C10: Rubriques vides sur les fiches filières. | D10: Coordonnateurs de filière / direction EIDIA | E10: Q021 | F10: Moyenne
A11: 7 | B11: Langue d'enseignement par filière | C11: Non précisée sur les fiches filières. | D11: Direction EIDIA | E11: Q020 | F11: Moyenne
A12: 8 | B12: Liste des masters ouverts en 2026-2027 | C12: La page de l'école et la plaquette 2026 ne concordent pas. | D12: Direction EIDIA | E12: Q016, Q034 | F12: Moyenne
A13: 9 | B13: Conditions d'admission par niveau d'entrée | C13: Mise en page décalée dans la plaquette 2026. | D13: Service des admissions | E13: Q022, Q023, Q024 | F13: Moyenne
A14: 10 | B14: Procédure de demande de bourse (dates, pièces, plateforme), y compris pour les étudiants déjà inscrits | C14: Types de bourses publiés, mais pas la procédure. | D14: Service de scolarité | E14: Q043, Q044 | F14: Moyenne
A15: 11 | B15: Téléphone et e-mail propres à l'EIDIA | C15: Le numéro affiché est le même que celui de la FSHS. | D15: Direction EIDIA | E15: Q064 | F15: Moyenne
A16: 12 | B16: Domaines e-mail des coordonnateurs (insa., emida.) | C16: Adresses à confirmer avant de les diffuser par l'assistant. | D16: Direction EIDIA | E16: Q010, Q015, Q067 | F16: Basse
... A19: 15 | B19: Informations sur les nouveaux bâtiments du campus | C19: Question du sondage sans source officielle. | D19: Communication UEMF | E19: Q071 | F19: Basse
